Workbook

Sheet 📖 INSTRUCCIONES
A1: GUÍA DE USO: TRACKER HALO-ESG
A3: 1. ¿QUÉ ES ESTE TRACKER?
A5: Este Excel te permite hacer seguimiento de tu 'Índice HALO personalizado' con enfoque ESG/inversión responsable.
A7: HALO = Heavy Assets, Low Obsolescence (activos físicos pesados, baja obsolescencia)
A8: Empresas intensivas en infraestructuras, maquinaria, redes... menos vulnerables a disrupción por IA.
A10: El tracker incluye 18 empresas HALO seleccionadas por compatibilidad razonable con criterios ESG:
A11: • Utilities con transición renovables (NEE, EXC, IBE, ORSTED, EDP)
A12: • Infraestructura de agua (AWK, XYL, ECL)
A13: • Economía circular (WM)
A14: • Ferrocarriles (UNP, CNI)
A15: • REIT sostenible (PLD, PSA)
A16: • Servicios esenciales (SCI, ROL, TT)
A18: 2. ESTRUCTURA DEL ARCHIVO (4 PESTAÑAS)
A20: Pestaña | B20: Contenido | C20: Para qué sirve
A21: HALO_ESG_Index | B21: 18 empresas con todas las métricas | C21: Base de datos principal - aquí actualizas los números
A22: Clasificación_3_Pasos | B22: Framework ESG en 3 pasos | C22: Sistema de clasificación Verde/Mixto/Excluido y análisis
A23: HALO_Completo_Comparativa | B23: 28 empresas (18+4+6) | C23: Comparar ESG vs no-ESG, ver qué excluyes y por qué
A24: Fuentes_ESG | B24: Enlaces y rutinas actualización | C24: Saber dónde buscar datos y con qué frecuencia
A26: 3. CÓMO ACTUALIZAR LOS DATOS (PASO A PASO)
A28: ACTUALIZACIÓN RÁPIDA (15-30 minutos) - Hazlo mensual o cuando entres al espacio
A30: PASO | B30: Acción | C30: Dónde | D30: Columnas a rellenar
A31: 1 | B31: Ir a Yahoo Finance | C31: finance.yahoo.com
A32: 2 | B32: Buscar el ticker (ej. NEE) | C32: Barra de búsqueda
A33: 3 | B33: Copiar datos de la página Summary:
B34: • Precio actual | C34: Primer número grande arriba | D34: Columna E
B35: • Variación 1 día (%) | C35: Al lado del precio, en verde/rojo | D35: Columna F
B36: • P/E (PER) | C36: Tabla derecha, 'PE Ratio (TTM)' | D36: Columna N
B37: • Beta | C37: Tabla derecha, 'Beta (5Y Monthly)' | D37: Columna Q
B38: • Dividend Yield | C38: Tabla derecha, 'Forward Dividend & Yield' | D38: Columna R
A39: 4 | B39: Ir a pestaña 'Analysis' en Yahoo | C39: Menú horizontal
B40: • Rating consenso | C40: Sección 'Recommendation Trend' | D40: Columna S (Buy/Hold/Sell)
B41: • Precio objetivo | C41: 'Price Target' arriba | D41: Columna T
A42: 5 | B42: El potencial % se calcula solo | C42: Fórmula en columna U | D42: Columna U (automático)
A43: 6
A46: ACTUALIZACIÓN COMPLETA (2-3 horas) - Hazlo trimestral
A48: Además de lo anterior, actualiza:
A49: • Rentabilidades 12m, 3a, 5a (columnas G, H, I) → Yahoo Finance > pestaña 'Performance'
A50: • Crecimiento ingresos/BPA (columnas K, M) → Investing.com > [ticker] > 'Financials'
A51: • Deuda Neta/EBITDA (columna P) → Investing.com > [ticker] > 'Ratios'
A52: • Lee earnings calls recientes para detectar cambios estratégicos
...

Sheet HALO_ESG_Index
A1: Ticker | B1: Nombre Empresa | C1: País/Mercado | D1: Sector | E1: Precio Actual | F1: Var. 1D (%) | G1: Rent. 12m (%) | H1: Rent. 3a (%) | I1: Rent. 5a (%) | J1: Ingresos LTM | K1: Crec. Ing. 3a (%) | L1: BPA Actual | M1: Crec. BPA 3a (%) | N1: PER Actual | O1: PER Medio 5a | P1: Deuda Neta/EBITDA | Q1: Beta | R1: Div. Yield (%) | S1: Rating Consenso | T1: Precio Objetivo 12m | U1: Potencial (%) | V1: Categoría ESG | W1: Notas ESG y Justificación
A2: NEE | B2: NextEra Energy | C2: US | D2: Utility Renovables | U2: =IF(E2>0,(T2-E2)/E2*100,"") | V2: Verde/Aceptable | W2: Líder USA renovables, 37 GW capacidad limpia, objetivo Real Zero 2045, inversión $74.6B 2025-2029. investor.nexteraenergy.com/sustainability
A3: EXC | B3: Exelon | C3: US | D3: Utility Regulada | U3: =IF(E3>0,(T3-E3)/E3*100,"") | V3: Verde/Aceptable | W3: Path to Clean: -50% emisiones 2030, Net Zero 2050, ya evitó 8.7M ton CO2, utilities reguladas 6 estados. exeloncorp.com/sustainability
A4: DUK | B4: Duke Energy | C4: US | D4: Utility | U4: =IF(E4>0,(T4-E4)/E4*100,"") | V4: Verde/Aceptable | W4: Utility regulada con plan transición energética, infraestructura crítica, compromiso descarbonización progresivo
A5: SO | B5: Southern Company | C5: US | D5: Utility | U5: =IF(E5>0,(T5-E5)/E5*100,"") | V5: Verde/Aceptable | W5: Utility integrada sureste USA, objetivos reducción emisiones, mix energético en transición
A6: IBE | B6: Iberdrola | C6: ES/EU | D6: Utility Renovables | U6: =IF(E6>0,(T6-E6)/E6*100,"") | V6: Verde/Aceptable | W6: Eléctrica más sostenible mundo 7 años consecutivos Clean200, 85% producción libre emisiones, 37→95 GW renovables 2030, Score ESG=1 S&P Global. iberdrola.com/sustainability
A7: ORSTED | B7: Ørsted | C7: DK/EU | D7: Eólica Offshore | U7: =IF(E7>0,(T7-E7)/E7*100,"") | V7: Verde/Aceptable | W7: Líder mundial eólica offshore, transformación carbón→100% renovables, referencia transición energética, activos marinos larga vida
A8: EDP | B8: EDP Renováveis | C8: PT/EU | D8: Renovables | U8: =IF(E8>0,(T8-E8)/E8*100,"") | V8: Verde/Aceptable | W8: Renovables puras, fuerte presencia eólica/solar Europa-Norteamérica, modelo 100% energías limpias
A9: AWK | B9: American Water Works | C9: US | D9: Agua | U9: =IF(E9>0,(T9-E9)/E9*100,"") | V9: Verde/Aceptable | W9: Top 5 Newsweek Most Responsible, 9 informes anuales sostenibilidad, infraestructura crítica agua limpia. ir.amwater.com/sustainability
A10: XYL | B10: Xylem | C10: US | D10: Agua/Tecnología | U10: =IF(E10>0,(T10-E10)/E10*100,"") | V10: Verde/Aceptable | W10: Líder tecnología agua, habilitó reutilización 18.1B m³ desde 2019, redujo 6.4M ton CO2, objetivo 2030: -2B m³/año demanda. xylem.com/sustainability
A11: ECL | B11: Ecolab | C11: US | D11: Agua/Sostenibilidad | U11: =IF(E11>0,(T11-E11)/E11*100,"") | V11: Verde/Aceptable | W11: Doble A CDP (agua+clima) 7º año, clientes ahorraron 226B galones 2023, objetivo 300B/año 2030, evitó 4.6M ton GEI 2024. ecolab.com/corporate-responsibility
A12: WM | B12: Waste Management | C12: US | D12: Residuos | U12: =IF(E12>0,(T12-E12)/E12*100,"") | V12: Verde/Aceptable | W12: Liderazgo sostenibilidad, Chief Sustainability Officer, reciclaje + gas vertedero para energía, economía circular. wm.com/sustainability
A13: TT | B13: Trane Technologies | C13: US | D13: Eficiencia Energética | U13: =IF(E13>0,(T13-E13)/E13*100,"") | V13: Verde/Aceptable | W13: Soluciones HVAC industrial, foco eficiencia energética edificios y refrigeración sostenible, reducción emisiones clientes
... A19: ROL | B19: Rollins | C19: US | D19: Control de Plagas | U19: =IF(E19>0,(T19-E19)/E19*100,"") | V19: Verde/Aceptable | W19: Red servicios físicos control plagas, sector salud pública, infraestructura regional, no sustituible por IA
A21: PROMEDIO CESTA ESG-18 | E21: =PROMEDIO(E2:E19) -> #NAME? | F21: =PROMEDIO(F2:F19) -> #NAME? | G21: =PROMEDIO(G2:G19) -> #NAME? | H21: =PROMEDIO(H2:H19) -> #NAME? | I21: =PROMEDIO(I2:I19) -> #NAME? | K21: =PROMEDIO(K2:K19) -> #NAME? | M21: =PROMEDIO(M2:M19) -> #NAME? | N21: =PROMEDIO(N2:N19) -> #NAME? | O21: =PROMEDIO(O2:O19) -> #NAME? | P21: =PROMEDIO(P2:P19) -> #NAME? | Q21: =PROMEDIO(Q2:Q19) -> #NAME? | R21: =PROMEDIO(R2:R19) -> #NAME? | U21: =PROMEDIO(U2:U19) -> #NAME?

Sheet Clasificación_3_Pasos
A1: ENFOQUE PRÁCTICO ESG EN TRES PASOS
A3: PASO 1: CLASIFICACIÓN EN 3 GRUPOS
A5: ✅ VERDE/ACEPTABLE (18 empresas HALO-ESG core)
A6: Utilities transición: | B6: NEE, EXC, DUK, SO, IBE, ORSTED, EDP
A7: Agua/soluciones ambientales: | B7: AWK, XYL, ECL
A8: Economía circular: | B8: WM
A9: Infraestructura baja emisión: | B9: UNP, CNI
A10: REIT sostenible: | B10: PLD, PSA
A11: Servicios esenciales: | B11: SCI, ROL
A12: Eficiencia energética: | B12: TT
A14: ⚠️ MIXTO/BAJO OBSERVACIÓN
A15: Consumo defensivo con retos: | B15: KO, MCD, WMT - Plásticos, cadena suministro, condiciones laborales
A16: Utilities tradicionales: | B16: Transición lenta a renovables
A17: Otros ferrocarriles: | B17: CSX - Buena infraestructura pero menos visibilidad ESG que UNP/CNI
A19: ❌ EXCLUIDO/NO ALINEADO
A20: Petroleras: | B20: XOM, CVX - Sin compromiso París, demandas a accionistas climáticos
A21: Mineras con controversias: | B21: RIO, BHP - Juukan Gorge, contaminación agua, suspenso ESG
A22: Oleoductos fósiles: | B22: ENB - Riesgo fugas, ligado a fósiles sin plan transición claro
A23: Defensa (opcional): | B23: LMT - Exclusión temática armas si aplica tu marco
A25: PASO 2: SUBÍNDICE HALO-ESG
A27: Métrica | B27: Cesta ESG-18 | C27: HALO Completo-20 | D27: Diferencial | E27: S&P 500 | F27: vs Benchmark
A28: Rentabilidad 12m (%) | B28: =HALO_ESG_Index!G21 -> #NAME? | C28: (dato manual) | D28: =B28-C28 -> #NAME? | E28: (dato manual) | F28: =B28-E28 -> #NAME?
A29: Rentabilidad 3a (%) | B29: =HALO_ESG_Index!H21 -> #NAME? | C29: (dato manual) | D29: =B29-C29 -> #NAME? | E29: (dato manual) | F29: =B29-E29 -> #NAME?
A30: Rentabilidad 5a (%) | B30: =HALO_ESG_Index!I21 -> #NAME? | C30: (dato manual) | D30: =B30-C30 -> #NAME? | E30: (dato manual) | F30: =B30-E30 -> #NAME?
A31: PER medio | B31: =HALO_ESG_Index!N21 -> #NAME? | C31: (dato manual) | D31: =B31-C31 -> #NAME? | E31: (dato manual) | F31: =B31-E31 -> #NAME?
A32: Beta medio | B32: =HALO_ESG_Index!Q21 -> #NAME? | C32: (dato manual) | D32: =B32-C32 -> #NAME? | E32: (dato manual) | F32: =B32-E32 -> #NAME?
A33: Div. Yield medio (%) | B33: =HALO_ESG_Index!R21 -> #NAME? | C33: (dato manual) | D33: =B33-C33 -> #NAME? | E33: (dato manual) | F33: =B33-E33 -> #NAME?
A36: PASO 3: REVISIÓN PERIÓDICA
A38: CHECKLIST TRIMESTRAL:
A39: ☐ | B39: Revisar informes sostenibilidad nuevos (columna W pestaña 1 tiene enlaces)
A40: ☐ | B40: Consultar Morningstar Sustainalytics ratings actualizados
A41: ☐ | B41: Buscar controversias ESG en Yahoo Finance [ticker]/sustainability
A42: ☐ | B42: Verificar CDP A-List anual (publicación feb-marzo)
A43: ☐ | B43: Comprobar S&P Global ESG Scores
A44: ☐ | B44: Leer Clean200 ranking anual (feb) - iberdrola.com
A46: ALERTAS A VIGILAR:
A47: Empresa | B47: Métrica clave a seguir | C47: Fuente
A48: IBE | B48: Progreso hacia 95 GW renovables 2030 | C48: Informes trimestrales Iberdrola
A49: XYL, ECL | B49: Cumplimiento objetivos agua 2030 (2B m³, 300B galones) | C49: Informes anuales sostenibilidad
A50: NEE | B50: Avance Real Zero 2045 y proyectos offshore | C50: investor.nexteraenergy.com
...

Sheet HALO_Completo_Comparativa
A1: Ticker | B1: Empresa | C1: Sector | D1: Categoría ESG | E1: Razón exclusión/inclusión | F1: Rent. 12m (%) | G1: Rent. 3a (%)
A2: NEE | B2: NextEra Energy | C2: Utility Renovables | D2: ✅ Verde | E2: Líder renovables USA
A3: EXC | B3: Exelon | C3: Utility Regulada | D3: ✅ Verde | E3: Path to Clean, Net Zero 2050
A4: DUK | B4: Duke Energy | C4: Utility | D4: ✅ Verde | E4: Transición energética
A5: SO | B5: Southern Company | C5: Utility | D5: ✅ Verde | E5: Objetivos descarbonización
A6: IBE | B6: Iberdrola | C6: Utility Renovables | D6: ✅ Verde | E6: Más sostenible mundo 7 años
A7: ORSTED | B7: Ørsted | C7: Eólica Offshore | D7: ✅ Verde | E7: 100% renovables
A8: EDP | B8: EDP Renováveis | C8: Renovables | D8: ✅ Verde | E8: Renovables puras
A9: AWK | B9: American Water Works | C9: Agua | D9: ✅ Verde | E9: Top 5 Most Responsible
A10: XYL | B10: Xylem | C10: Agua/Tecnología | D10: ✅ Verde | E10: Líder tecnología agua
A11: ECL | B11: Ecolab | C11: Agua/Sostenibilidad | D11: ✅ Verde | E11: Doble A CDP
A12: WM | B12: Waste Management | C12: Residuos | D12: ✅ Verde | E12: Economía circular
A13: TT | B13: Trane Technologies | C13: Eficiencia Energética | D13: ✅ Verde | E13: HVAC sostenible
... A29: LMT | B29: Lockheed Martin | C29: Defensa | D29: ❌ Excluido | E29: Exclusión temática armas (opcional)
A31: PROMEDIO VERDES (18) | F31: =PROMEDIO(F2:F19) -> #NAME? | G31: =PROMEDIO(G2:G19) -> #NAME?
A32: PROMEDIO MIXTAS (4) | F32: =PROMEDIO(F20:F23) -> #NAME? | G32: =PROMEDIO(G20:G23) -> #NAME?
A33: PROMEDIO EXCLUIDAS (6) | F33: =PROMEDIO(F24:F29) -> #NAME? | G33: =PROMEDIO(G24:G29) -> #NAME?
A34: PROMEDIO TOTAL (28) | F34: =PROMEDIO(F2:F29) -> #NAME? | G34: =PROMEDIO(G2:G29) -> #NAME?

Sheet Fuentes_ESG
A1: FUENTES PARA ACTUALIZACIÓN ESG
A3: Ticker | B3: Yahoo Finance ESG | C3: Web Corporativa Sostenibilidad | D3: Notas
A4: NEE | B4: finance.yahoo.com/quote/NEE/sustainability | C4: investor.nexteraenergy.com/sustainability | D4: Informes anuales + ESG Report
A5: EXC | B5: finance.yahoo.com/quote/EXC/sustainability | C5: exeloncorp.com/sustainability | D5: Path to Clean docs
A6: IBE | B6: finance.yahoo.com/quote/IBE/sustainability | C6: iberdrola.com/sustainability | D6: Clean200 líder, informes trimestrales
A7: AWK | B7: finance.yahoo.com/quote/AWK/sustainability | C7: ir.amwater.com/sustainability | D7: Newsweek Top 5
A8: XYL | B8: finance.yahoo.com/quote/XYL/sustainability | C8: xylem.com/sustainability | D8: Net Zero Carbon Champion
A9: ECL | B9: finance.yahoo.com/quote/ECL/sustainability | C9: ecolab.com/corporate-responsibility | D9: CDP doble A, Water for Climate
A10: WM | B10: finance.yahoo.com/quote/WM/sustainability | C10: wm.com/sustainability | D10: CEO Jim Fish interviews
A11: Otros | B11: finance.yahoo.com/quote/[TICKER]/sustainability | C11: [Buscar investor relations] | D11: Sección ESG/Sustainability
A13: FUENTES EXTERNAS CLAVE
A15: Plataforma | B15: URL | C15: Qué buscar | D15: Frecuencia
A16: Morningstar Sustainalytics | B16: morningstar.com > buscar ticker > ESG | C16: ESG Risk Score (Low/Medium/High) | D16: Trimestral
A17: CDP (Climate Disclosure) | B17: cdp.net | C17: A-List anual, scores agua/clima | D17: Anual (feb-mar)
A18: Clean200 | B18: clean200.org | C18: Ranking energías limpias | D18: Anual (feb)
A19: Investing.com ESG | B19: investing.com/equities/[ticker] > ESG tab | C19: Noticias ESG recientes | D19: Mensual
A20: S&P Global ESG Scores
A22: RUTINA DE ACTUALIZACIÓN RECOMENDADA
A24: Frecuencia | B24: Acción | C24: Fuente | D24: Tiempo estimado
A25: Semanal | B25: Revisar noticias ESG 18 empresas | C25: Yahoo Finance ESG News | D25: 15 min
A26: Mensual | B26: Actualizar precios y métricas | C26: Yahoo Finance + Investing.com | D26: 30 min
A27: Trimestral | B27: Leer earnings calls + informes | C27: Investor Relations + Morningstar | D27: 2-3 horas
A28: Anual | B28: Informes sostenibilidad completos | C28: Webs corporativas | D28: 1 día
A29: Anual (feb-mar) | B29: CDP A-List + Clean200 | C29: cdp.net + clean200.org | D29: 1 hora
